Workbook

Sheet Total 
B5: Total Per Community | G5: Total Per 8 Communities
B6: OVERHEADS | C6: TOTAL | G6: OVERHEADS | H6: TOTAL
B7: ='Break Down Per Community'!B2 -> Personnel Expenses | C7: ='Break Down Per Community'!E11 -> 420000 | G7: =B7 -> Personnel Expenses | H7: ='Total Breakdown'!AC36 -> 3360000
B8: ='Break Down Per Community'!B13 -> Equipment and Supplies | C8: ='Break Down Per Community'!E20 -> 61645000 | G8: =B8 -> Equipment and Supplies | H8: ='Total Breakdown'!AC45 -> 365160000
B9: ='Break Down Per Community'!B22 -> Training and Educaton | C9: ='Break Down Per Community'!E29 -> 570000 | G9: =B9 -> Training and Educaton | H9: ='Total Breakdown'!AC54 -> 4560000
B10: ='Break Down Per Community'!B31 -> Outreach and Mobilization | C10: ='Break Down Per Community'!E39 -> 7900000 | G10: =B10 -> Outreach and Mobilization | H10: ='Total Breakdown'!AC64 -> 63200000
B11: ='Break Down Per Community'!B41 -> Facilities and Infrastructure | C11: ='Break Down Per Community'!E48 -> 240000 | G11: =B11 -> Facilities and Infrastructure | H11: ='Total Breakdown'!AC73 -> 1920000
B12: ='Break Down Per Community'!G2 -> Monitoring and Evaluation | C12: ='Break Down Per Community'!J11 -> 1847000 | E12: 1004159407 | G12: =B12 -> Monitoring and Evaluation | H12: ='Total Breakdown'!AC84 -> 14776000
B13: ='Break Down Per Community'!G13 -> Administrative and Overhead Costs | C13: ='Break Down Per Community'!J20 -> 1900000 | G13: =B13 -> Administrative and Overhead Costs | H13: ='Total Breakdown'!AC93 -> 15200000
B14: ='Break Down Per Community'!G22 -> Security | C14: ='Break Down Per Community'!J28 -> 300000 | G14: =B14 -> Security | H14: ='Total Breakdown'!AC101 -> 2400000
B15: ='Break Down Per Community'!G31 -> Contingency Funds | C15: ='Break Down Per Community'!J36 -> 1000000 | G15: =B15 -> Contingency Funds | H15: ='Total Breakdown'!AC108 -> 8000000
C16: 0 | H16: 0
B17: Projected End Balance | C17: =SUM(C7:C16) -> 75822000 | G17: Projected End Balance | H17: =SUM(H7:H16) -> 478576000

Sheet Break Down Per Community
B2: Personnel Expenses | C2: Cost | D2: Frequency | E2: Total | G2: Monitoring and Evaluation | H2: =C13 -> Cost | I2: =D2 -> Frequency | J2: =E2 -> Total
B3: Wages for Medical Doctor | C3: 80000 | D3: 2 | E3: =C3*D3 -> 160000 | G3: Data Collection and Analysis | I3: 1 | J3: =H3*I3 -> 0
B4: Wages for Nurse | C4: 50000 | D4: 2 | E4: =C4*D4 -> 100000 | G4: Evaluation Studies | I4: 1 | J4: =H4*I4 -> 0
B5: Wages for outreach Staff | C5: 40000 | D5: 4 | E5: =C5*D5 -> 160000 | G5: IT Infrastructure and Data Management | I5: 1 | J5: =H5*I5 -> 0
E6: =C6*D6 -> 0 | G6: Portable Tablets | H6: 200000 | I6: 2 | J6: =H6*I6 -> 400000
E7: =C7*D7 -> 0 | G7: Laptop | H7: 300000 | I7: 1 | J7: =H7*I7 -> 300000
E8: =C8*D8 -> 0 | G8: Projector and white screen | H8: 400000 | I8: 1 | J8: =H8*I8 -> 400000
E9: =C9*D9 -> 0 | G9: Internet Routers and Subsription | H9: 30000 | I9: 3 | J9: =H9*I9 -> 90000
E10: =C10*D10 -> 0 | G10: Back Up Power Supply and Mini Inverters | H10: 219000 | I10: 3 | J10: =H10*I10 -> 657000
B11: =B2&" totals" -> Personnel Expenses totals | C11: =SUM(C3:C10) -> 170000 | D11: =SUM(D3:D10) -> 8 | E11: =SUM(E3:E10) -> 420000 | G11: =G2&" totals" -> Monitoring and Evaluation totals | H11: =SUM(H3:H10) -> 1149000 | I11: =SUM(I3:I10) -> 13 | J11: =SUM(J3:J10) -> 1847000
B13: Equipment and Supplies | C13: =C2 -> Cost | D13: Frequency | E13: Total | G13: Administrative and Overhead Costs | H13: =C13 -> Cost | I13: =I2 -> Frequency | J13: =J2 -> Total
B14: Procurement for HPV Sampling | C14: 1500 | D14: 2000 | E14: =C14*D14 -> 3000000 | G14: Rent | H14: 500000 | I14: 1 | J14: =H14*I14 -> 500000
B15: Labotory Analysis | C15: 7822.5 | D15: 2000 | E15: =C15*D15 -> 15645000 | G15: Utilities | H15: 150000 | I15: 1 | J15: =H15*I15 -> 150000
B16: Gynescope | C16: 11250 | D16: 2000 | E16: =C16*D16 -> 22500000 | G16: Inverter Maintenance | I16: 1 | J16: =H16*I16 -> 0
B17: Medical Supply and consumables | C17: 2250 | D17: 2000 | E17: =C17*D17 -> 4500000 | G17: Communication | H17: 150000 | I17: 1 | J17: =H17*I17 -> 150000
B18: Logistics | C18: 8000 | D18: 2000 | E18: =C18*D18 -> 16000000 | G18: Stationeries | H18: 500000 | I18: 1 | J18: =H18*I18 -> 500000
E19: =C19*D19 -> 0 | G19: Insurance and Legal Fees | H19: 37500 | I19: 16 | J19: =H19*I19 -> 600000
B20: =B13&" totals" -> Equipment and Supplies totals | C20: =SUM(C14:C19) -> 30822.5 | D20: =SUM(D14:D19) -> 10000 | E20: =SUM(E14:E19) -> 61645000 | G20: =G13&" totals" -> Administrative and Overhead Costs totals | H20: =SUM(H14:H18) -> 1300000 | I20: =SUM(I14:I19) -> 21 | J20: =SUM(J14:J19) -> 1900000
B22: Training and Educaton | C22: =C13 -> Cost | D22: Frequency | E22: Total | G22: Security | H22: =C31 -> Cost | I22: =I13 -> Frequency | J22: =J13 -> Total
B23: Training Programs | C23: 570000 | D23: 1 | E23: =C23*D23 -> 570000 | G23: Security Personnel | H23: 50000 | I23: 6 | J23: =H23*I23 -> 300000
B24: Education Materials | C24: 0 | D24: 1 | E24: =C24*D24 -> 0 | J24: =H24*I24 -> 0
E25: =C25*D25 -> 0 | J25: =H25*I25 -> 0
E26: =C26*D26 -> 0 | J26: =H26*I26 -> 0
E27: =C27*D27 -> 0 | J27: =H27*I27 -> 0
E28: =C28*D28 -> 0 | G28: =G22&" totals" -> Security totals | H28: =SUM(H23:H27) -> 50000 | I28: =SUM(I23:I27) -> 6 | J28: =SUM(J23:J27) -> 300000
B29: =B22&" totals" -> Training and Educaton totals | C29: =SUM(C23:C28) -> 570000 | D29: =SUM(D23:D28) -> 2 | E29: =SUM(E23:E28) -> 570000
B31: Outreach and Mobilization | C31: =C22 -> Cost | D31: Frequency | E31: =E22 -> Total | G31: Contingency Funds | H31: =C31 -> Cost | I31: =I22 -> Frequency | J31: =J22 -> Total
B32: Community Engagement | C32: 200000 | D32: 10 | E32: =C32*D32 -> 2000000 | G32: Emergency Funds | H32: 1000000 | I32: 1 | J32: =H32*I32 -> 1000000
B33: Transportation and Logistics for the devices | C33: 1000000 | D33: 1 | E33: =C33*D33 -> 1000000 | J33: =H33*I33 -> 0
B34: Radio Ad | C34: 500000 | D34: 1 | E34: =C34*D34 -> 500000 | J34: =H34*I34 -> 0
B35: Content Creation & Social Media Promotions | C35: 400000 | D35: 1 | E35: =C35*D35 -> 400000 | J35: =H35*I35 -> 0
B36: Brochures, Flyers and Posters | C36: 1000000 | D36: 1 | E36: =C36*D36 -> 1000000 | G36: =G31&" totals" -> Contingency Funds totals | H36: =SUM(H32:H35) -> 1000000 | I36: =SUM(I32:I35) -> 1 | J36: =SUM(J32:J35) -> 1000000
B37: Souvenirs | C37: 1500 | D37: 2000 | E37: =C37*D37 -> 3000000
E38: =C38*D38 -> 0
B39: =B31&" totals" -> Outreach and Mobilization totals | C39: =SUM(C32:C38) -> 3101500 | D39: =SUM(D32:D38) -> 2014 | E39: =SUM(E32:E38) -> 7900000
B41: Facilities and Infrastructure | C41: =C31 -> Cost | D41: =D31 -> Frequency | E41: =E31 -> Total
B42: Renovation and Construction | C42: 0 | D42: 1 | E42: =C42*D42 -> 0
B43: Furnitures and Fittings | C43: 120000 | D43: 2 | E43: =C43*D43 -> 240000
E44: =C44*D44 -> 0
E45: =C45*D45 -> 0
...

Sheet Total Breakdown
A7: MONTH | G7: Communities | J7: 8
A9: Name of Community | B9: Community 1 | E9: Community 2 | H9: Community 3 | K9: Community 4 | N9: Community 5 | Q9: Community 6 | T9: Community 7 | W9: Community 8 | AA9: MONTH TO DATE
A10: Population
A11: WEEKLY BUDGET SUMMARY | B11: Cost | C11: Frequency | D11: Total | E11: Cost | F11: Frequency | G11: Total | H11: Cost | I11: Frequency | J11: Total | K11: Cost | L11: Frequency | M11: Total | N11: Cost | O11: Frequency | P11: Total | Q11: Cost | R11: Frequency | S11: Total | T11: Cost | U11: Frequency | V11: Total | W11: Cost | X11: Frequency | Y11: Total | AA11: Cost | AB11: Frequency | AC11: Total
A12: Starting Balance | B12: =C12 -> 15 | C12: 15 | D12: =C12*B12 -> 225 | E12: =B16 -> -7520777.5 | F12: =C16 -> -9993 | G12: =F12-E12 -> 7510784.5 | H12: =E16 -> -15041575 | I12: =F16 -> -20026 | J12: =I12-H12 -> 15021549 | K12: =H16 -> -22562372 | L12: =I16 -> -30084 | M12: =L12-K12 -> 22532288 | N12: =IF($J$7=4,0,K16) -> -30083195 | O12: =IF($J$7=4,0,L16) -> -40152 | P12: =O12-N12 -> 30043043 | Q12: =N16 -> -37604018 | R12: =O16 -> -50220 | S12: =R12-Q12 -> 37553798 | T12: =Q16 -> -45124815 | U12: =R16 -> -60278 | V12: =U12-T12 -> 45064537 | W12: =IF($J$7=4,0,T16) -> -52645638 | X12: =IF($J$7=4,0,U16) -> -70346 | Y12: =X12-W12 -> 52575292 | AA12: =SUM(B12,E12,H12,K12,IF($J$7=5,N12,0))-B12-E12-H12-IF($J$7=5,K12,0) -> -22562372 | AB12: =SUM(C12,F12,I12,L12,IF($J$7=5,O12,0))-C12-F12-I12-IF($J$7=5,L12,0) -> -30084 | AC12: =AB12-AA12 -> 22532288
A13: Total Income | B13: =B25 -> 30 | C13: =C25 -> 60 | D13: =C13*B13 -> 1800 | E13: =E25 -> 25 | F13: =F25 -> 35 | G13: =F13-E13 -> 10 | H13: =H25 -> 25 | I13: =I25 -> 10 | J13: =I13-H13 -> -15 | K13: =K25 -> 0 | L13: =L25 -> 0 | M13: =L13-K13 -> 0 | N13: =N25 -> 0 | O13: =O25 -> 0 | P13: =IF($J$7=5,O13-N13,0) -> 0 | Q13: =Q25 -> 25 | R13: =R25 -> 10 | S13: =R13-Q13 -> -15 | T13: =T25 -> 0 | U13: =U25 -> 0 | V13: =U13-T13 -> 0 | W13: =W25 -> 0 | X13: =X25 -> 0 | Y13: =IF($J$7=5,X13-W13,0) -> 0 | AA13: =AA25 -> 80 | AB13: =SUM(C13,F13,I13,L13,IF($J$7=5,O13,0)) -> 105 | AC13: =SUM(C13,F13,I13,L13,IF($J$7=5,O13,0))-SUM(B13,E13,H13,K13,IF($J$7=5,N13,0)) -> 25
A14: Total Expenses | B14: =B36+B45+B54+B64+B73+B84+B93+B101+B108+B115+B123 -> 7520822.5 | C14: =C36+C45+C54+C64+C73+C84+C93+C101+C108+C115+C123 -> 10068 | D14: =C14*B14 -> 75719640930 | E14: =E36+E45+E54+E64+E73+E84+E93+E101+E108+E115+E123 -> 7520822.5 | F14: =F36+F45+F54+F64+F73+F84+F93+F101+F108+F115+F123 -> 10068 | G14: =E14-F14 -> 7510754.5 | H14: =H36+H45+H54+H64+H73+H84+H93+H101+H108+H115+H123 -> 7520822.5 | I14: =I36+I45+I54+I64+I73+I84+I93+I101+I108+I115+I123 -> 10068 | J14: =H14-I14 -> 7510754.5 | K14: =K36+K45+K54+K64+K73+K84+K93+K101+K108+K115+K123 -> 7520822.5 | L14: =L36+L45+L54+L64+L73+L84+L93+L101+L108+L115+L123 -> 10068 | M14: =K14-L14 -> 7510754.5 | N14: =N36+N45+N54+N64+N73+N84+N93+N101+N108+N115+N123 -> 7520822.5 | O14: =O36+O45+O54+O64+O73+O84+O93+O101+O108+O115+O123 -> 10068 | P14: =IF($J$7=5,O14-N14,0) -> 0 | Q14: =Q36+Q45+Q54+Q64+Q73+Q84+Q93+Q101+Q108+Q115+Q123 -> 7520822.5 | R14: =R36+R45+R54+R64+R73+R84+R93+R101+R108+R115+R123 -> 10068 | S14: =Q14-R14 -> 7510754.5 | T14: =T36+T45+T54+T64+T73+T84+T93+T101+T108+T115+T123 -> 7520822.5 | U14: =U36+U45+U54+U64+U73+U84+U93+U101+U108+U115+U123 -> 10068 | V14: =T14-U14 -> 7510754.5 | W14: =W36+W45+W54+W64+W73+W84+W93+W101+W108+W115+W123 -> 7520822.5 | X14: =X36+X45+X54+X64+X73+X84+X93+X101+X108+X115+X123 -> 10068 | Y14: =IF($J$7=5,X14-W14,0) -> 0 | AA14: =AA36+AA45+AA54+AA64+AA73+AA84+AA93+AA101+AA108+AA115+AA123 -> 60166580 | AB14: =SUM(C14,F14,I14,L14,IF($J$7=5,O14,0)) -> 40272 | AC14: =AA14-AB14 -> 60126308
A15: NET (Income - Expenses) | B15: =B13-B14 -> -7520792.5 | C15: =C13-C14 -> -10008 | D15: =C15*B15 -> 75268091340 | E15: =E13-E14 -> -7520797.5 | F15: =F13-F14 -> -10033 | G15: =E15-F15 -> -7510764.5 | H15: =H13-H14 -> -7520797.5 | I15: =I13-I14 -> -10058 | J15: =H15-I15 -> -7510739.5 | K15: =K13-K14 -> -7520822.5 | L15: =L13-L14 -> -10068 | M15: =K15-L15 -> -7510754.5 | N15: =N13-N14 -> -7520822.5 | O15: =O13-O14 -> -10068 | P15: =IF($J$7=5,O15-N15,0) -> 0 | Q15: =Q13-Q14 -> -7520797.5 | R15: =R13-R14 -> -10058 | S15: =Q15-R15 -> -7510739.5 | T15: =T13-T14 -> -7520822.5 | U15: =U13-U14 -> -10068 | V15: =T15-U15 -> -7510754.5 | W15: =W13-W14 -> -7520822.5 | X15: =X13-X14 -> -10068 | Y15: =IF($J$7=5,X15-W15,0) -> 0 | AA15: =AA13-AA14 -> -60166500 | AB15: =SUM(C15,F15,I15,L15,IF($J$7=5,O15,0)) -> -40167 | AC15: =SUM(C15,F15,I15,L15,IF($J$7=5,O15,0))-SUM(B15,E15,H15,K15,IF($J$7=5,N15,0)) -> 30043043
A16: Projected End Balance | B16: =B13-B14+B12 -> -7520777.5 | C16: =C13-C14+C12 -> -9993 | D16: =C16*B16 -> 7.515513e+10 | E16: =E13-E14+E12 -> -15041575 | F16: =F13-F14+F12 -> -20026 | G16: =F16-E16 -> 15021549 | H16: =H13-H14+H12 -> -22562372 | I16: =I13-I14+I12 -> -30084 | J16: =I16-H16 -> 22532288 | K16: =K13-K14+K12 -> -30083195 | L16: =L13-L14+L12 -> -40152 | M16: =L16-K16 -> 30043043 | N16: =N13-N14+N12 -> -37604018 | O16: =O13-O14+O12 -> -50220 | P16: =IF($J$7=5,O16-N16,0) -> 0 | Q16: =Q13-Q14+Q12 -> -45124815 | R16: =R13-R14+R12 -> -60278 | S16: =R16-Q16 -> 45064537 | T16: =T13-T14+T12 -> -52645638 | U16: =U13-U14+U12 -> -70346 | V16: =U16-T16 -> 52575292 | W16: =W13-W14+W12 -> -60166460 | X16: =X13-X14+X12 -> -80414 | Y16: =IF($J$7=5,X16-W16,0) -> 0 | AA16: =AA13-AA14+B12 -> -60166485 | AB16: =AB13-AB14+C12 -> -40152 | AC16: =AB16-AA16 -> 60126333
A18: INCOME | B18: =B11 -> Cost | C18: =C11 -> Frequency | D18: =D11 -> Total | E18: =E11 -> Cost | F18: =F11 -> Frequency | G18: =G11 -> Total | H18: =H11 -> Cost | I18: =I11 -> Frequency | ... Y18: =Y11 -> Total | AA18: =$AA$11 -> Cost | AB18: =$AB$11 -> Frequency | AC18: Difference
B19: 30 | C19: 60 | D19: =C19-B19 -> 30 | E19: 25 | F19: 35 | G19: =F19-E19 -> 10 | H19: 25 | I19: 10 | J19: =I19-H19 -> -15 | M19: =L19-K19 -> 0 | P19: =O19-N19 -> 0 | Q19: 25 | R19: 10 | S19: =R19-Q19 -> -15 | V19: =U19-T19 -> 0 | Y19: =X19-W19 -> 0 | AA19: =SUM(B19,E19,H19,K19,IF($J$7=5,N19,0)) -> 80 | AB19: =SUM(C19,F19,I19,L19,IF($J$7=5,O19,0)) -> 105 | AC19: =SUM(C19,F19,I19,L19,IF($J$7=5,O19,0))-SUM(B19,E19,H19,K19,IF($J$7=5,N19,0)) -> 25
D20: =C20-B20 -> 0 | G20: =F20-E20 -> 0 | J20: =I20-H20 -> 0 | M20: =L20-K20 -> 0 | P20: =O20-N20 -> 0 | S20: =R20-Q20 -> 0 | V20: =U20-T20 -> 0 | Y20: =X20-W20 -> 0 | AA20: =SUM(B20,E20,H20,K20,IF($J$7=5,N20,0)) -> 0 | AB20: =SUM(C20,F20,I20,L20,IF($J$7=5,O20,0)) -> 0 | AC20: =SUM(C20,F20,I20,L20,IF($J$7=5,O20,0))-SUM(B20,E20,H20,K20,IF($J$7=5,N20,0)) -> 0
D21: =C21-B21 -> 0 | G21: =F21-E21 -> 0 | J21: =I21-H21 -> 0 | M21: =L21-K21 -> 0 | P21: =O21-N21 -> 0 | S21: =R21-Q21 -> 0 | V21: =U21-T21 -> 0 | Y21: =X21-W21 -> 0 | AA21: =SUM(B21,E21,H21,K21,IF($J$7=5,N21,0)) -> 0 | AB21: =SUM(C21,F21,I21,L21,IF($J$7=5,O21,0)) -> 0 | AC21: =SUM(C21,F21,I21,L21,IF($J$7=5,O21,0))-SUM(B21,E21,H21,K21,IF($J$7=5,N21,0)) -> 0
D22: =C22-B22 -> 0 | G22: =F22-E22 -> 0 | J22: =I22-H22 -> 0 | M22: =L22-K22 -> 0 | P22: =O22-N22 -> 0 | S22: =R22-Q22 -> 0 | V22: =U22-T22 -> 0 | Y22: =X22-W22 -> 0 | AA22: =SUM(B22,E22,H22,K22,IF($J$7=5,N22,0)) -> 0 | AB22: =SUM(C22,F22,I22,L22,IF($J$7=5,O22,0)) -> 0 | AC22: =SUM(C22,F22,I22,L22,IF($J$7=5,O22,0))-SUM(B22,E22,H22,K22,IF($J$7=5,N22,0)) -> 0
D23: =C23-B23 -> 0 | G23: =F23-E23 -> 0 | J23: =I23-H23 -> 0 | M23: =L23-K23 -> 0 | P23: =O23-N23 -> 0 | S23: =R23-Q23 -> 0 | V23: =U23-T23 -> 0 | Y23: =X23-W23 -> 0 | AA23: =SUM(B23,E23,H23,K23,IF($J$7=5,N23,0)) -> 0 | AB23: =SUM(C23,F23,I23,L23,IF($J$7=5,O23,0)) -> 0 | AC23: =SUM(C23,F23,I23,L23,IF($J$7=5,O23,0))-SUM(B23,E23,H23,K23,IF($J$7=5,N23,0)) -> 0
D24: =C24-B24 -> 0 | G24: =F24-E24 -> 0 | J24: =I24-H24 -> 0 | M24: =L24-K24 -> 0 | P24: =O24-N24 -> 0 | S24: =R24-Q24 -> 0 | V24: =U24-T24 -> 0 | Y24: =X24-W24 -> 0 | AA24: =SUM(B24,E24,H24,K24,IF($J$7=5,N24,0)) -> 0 | AB24: =SUM(C24,F24,I24,L24,IF($J$7=5,O24,0)) -> 0 | AC24: =SUM(C24,F24,I24,L24,IF($J$7=5,O24,0))-SUM(B24,E24,H24,K24,IF($J$7=5,N24,0)) -> 0
A25: ="Total "&A18 -> Total INCOME | B25: =SUM(B19:B24) -> 30 | C25: =SUM(C19:C24) -> 60 | D25: =SUM(D19:D24) -> 30 | E25: =SUM(E19:E24) -> 25 | F25: =SUM(F19:F24) -> 35 | G25: =SUM(G19:G24) -> 10 | H25: =SUM(H19:H24) -> 25 | I25: =SUM(I19:I24) -> 10 | ... Y25: =SUM(Y19:Y24) -> 0 | AA25: =SUM(AA19:AA24) -> 80 | AB25: =SUM(C25,F25,I25,L25,IF($J$7=5,O25,0)) -> 105 | AC25: =SUM(AC19:AC24) -> 25
A27: ='Total '!B7 -> Personnel Expenses | B27: =$B$11 -> Cost | C27: =$C$11 -> Frequency | D27: =$D$11 -> Total | E27: =$E$11 -> Cost | F27: =$F$11 -> Frequency | G27: =$G$11 -> Total | H27: =$H$11 -> Cost | I27: =$I$11 -> Frequency | J27: =$J$11 -> Total | K27: =$K$11 -> Cost | L27: =$L$11 -> Frequency | M27: =$M$11 -> Total | N27: =$K$11 -> Cost | O27: =$L$11 -> Frequency | P27: =$M$11 -> Total | Q27: =$H$11 -> Cost | R27: =$I$11 -> Frequency | S27: =$J$11 -> Total | T27: =$K$11 -> Cost | U27: =$L$11 -> Frequency | V27: =$M$11 -> Total | W27: =$K$11 -> Cost | X27: =$L$11 -> Frequency | Y27: =$M$11 -> Total | AA27: =$AA$11 -> Cost | AB27: =$AB$11 -> Frequency | AC27: =$AC$11 -> Total
A28: ='Break Down Per Community'!B3 -> Wages for Medical Doctor | B28: ='Break Down Per Community'!C3 -> 80000 | C28: 2 | D28: =B28*C28 -> 160000 | E28: ='Break Down Per Community'!C3 -> 80000 | F28: ='Break Down Per Community'!D3 -> 2 | G28: ='Break Down Per Community'!E3 -> 160000 | H28: ='Break Down Per Community'!C3 -> 80000 | I28: ='Break Down Per Community'!D3 -> 2 | J28: ='Break Down Per Community'!E3 -> 160000 | K28: ='Break Down Per Community'!C3 -> 80000 | L28: ='Break Down Per Community'!D3 -> 2 | M28: ='Break Down Per Community'!E3 -> 160000 | N28: ='Break Down Per Community'!C3 -> 80000 | O28: ='Break Down Per Community'!D3 -> 2 | P28: ='Break Down Per Community'!E3 -> 160000 | Q28: ='Break Down Per Community'!C3 -> 80000 | R28: ='Break Down Per Community'!D3 -> 2 | S28: ='Break Down Per Community'!E3 -> 160000 | T28: ='Break Down Per Community'!C3 -> 80000 | U28: ='Break Down Per Community'!D3 -> 2 | V28: ='Break Down Per Community'!E3 -> 160000 | W28: =T28 -> 80000 | X28: =U28 -> 2 | Y28: =V28 -> 160000 | AA28: =SUM(B28,E28,H28,K28,N28,Q28,T28,W28) -> 640000 | AB28: =SUM(C28,F28,I28,L28,O28,R28,U28,X28) -> 16 | AC28: =SUM(D28,G28,J28,M28,P28,S28,V28,Y28) -> 1280000
A29: ='Break Down Per Community'!B4 -> Wages for Nurse | B29: ='Break Down Per Community'!C4 -> 50000 | C29: 2 | D29: =B29*C29 -> 100000 | E29: ='Break Down Per Community'!C4 -> 50000 | F29: ='Break Down Per Community'!D4 -> 2 | G29: ='Break Down Per Community'!E4 -> 100000 | H29: ='Break Down Per Community'!C4 -> 50000 | I29: ='Break Down Per Community'!D4 -> 2 | J29: ='Break Down Per Community'!E4 -> 100000 | K29: ='Break Down Per Community'!C4 -> 50000 | L29: ='Break Down Per Community'!D4 -> 2 | M29: ='Break Down Per Community'!E4 -> 100000 | N29: ='Break Down Per Community'!C4 -> 50000 | O29: ='Break Down Per Community'!D4 -> 2 | P29: ='Break Down Per Community'!E4 -> 100000 | Q29: ='Break Down Per Community'!C4 -> 50000 | R29: ='Break Down Per Community'!D4 -> 2 | S29: ='Break Down Per Community'!E4 -> 100000 | T29: ='Break Down Per Community'!C4 -> 50000 | U29: ='Break Down Per Community'!D4 -> 2 | V29: ='Break Down Per Community'!E4 -> 100000 | W29: =T29 -> 50000 | X29: =U29 -> 2 | Y29: =V29 -> 100000 | AA29: =SUM(B29,E29,H29,K29,N29,Q29,T29,W29) -> 400000 | AB29: =SUM(C29,F29,I29,L29,O29,R29,U29,X29) -> 16 | AC29: =SUM(D29,G29,J29,M29,P29,S29,V29,Y29) -> 800000
A30: ='Break Down Per Community'!B5 -> Wages for outreach Staff | B30: ='Break Down Per Community'!C5 -> 40000 | C30: 4 | D30: =B30*C30 -> 160000 | E30: ='Break Down Per Community'!C5 -> 40000 | F30: ='Break Down Per Community'!D5 -> 4 | G30: ='Break Down Per Community'!E5 -> 160000 | H30: ='Break Down Per Community'!C5 -> 40000 | I30: ='Break Down Per Community'!D5 -> 4 | J30: ='Break Down Per Community'!E5 -> 160000 | K30: ='Break Down Per Community'!C5 -> 40000 | L30: ='Break Down Per Community'!D5 -> 4 | M30: ='Break Down Per Community'!E5 -> 160000 | N30: ='Break Down Per Community'!C5 -> 40000 | O30: ='Break Down Per Community'!D5 -> 4 | P30: ='Break Down Per Community'!E5 -> 160000 | Q30: ='Break Down Per Community'!C5 -> 40000 | R30: ='Break Down Per Community'!D5 -> 4 | S30: ='Break Down Per Community'!E5 -> 160000 | T30: ='Break Down Per Community'!C5 -> 40000 | U30: ='Break Down Per Community'!D5 -> 4 | V30: ='Break Down Per Community'!E5 -> 160000 | W30: =T30 -> 40000 | X30: =U30 -> 4 | Y30: =V30 -> 160000 | AA30: =SUM(B30,E30,H30,K30,N30,Q30,T30,W30) -> 320000 | AB30: =SUM(C30,F30,I30,L30,O30,R30,U30,X30) -> 32 | AC30: =SUM(D30,G30,J30,M30,P30,S30,V30,Y30) -> 1280000
D31: =B31*C31 -> 0 | E31: ='Break Down Per Community'!C6 -> 0 | F31: ='Break Down Per Community'!D6 -> 0 | G31: ='Break Down Per Community'!E6 -> 0 | H31: ='Break Down Per Community'!C6 -> 0 | I31: ='Break Down Per Community'!D6 -> 0 | J31: ='Break Down Per Community'!E6 -> 0 | K31: ='Break Down Per Community'!C6 -> 0 | L31: ='Break Down Per Community'!D6 -> 0 | M31: ='Break Down Per Community'!E6 -> 0 | N31: ='Break Down Per Community'!C6 -> 0 | O31: ='Break Down Per Community'!D6 -> 0 | P31: ='Break Down Per Community'!E6 -> 0 | Q31: ='Break Down Per Community'!C6 -> 0 | R31: ='Break Down Per Community'!D6 -> 0 | S31: ='Break Down Per Community'!E6 -> 0 | T31: ='Break Down Per Community'!C6 -> 0 | U31: ='Break Down Per Community'!D6 -> 0 | V31: ='Break Down Per Community'!E6 -> 0 | W31: =T31 -> 0 | X31: =U31 -> 0 | Y31: =V31 -> 0 | AA31: =SUM(B31,E31,H31,K31,N31,Q31,T31,W31) -> 0 | AB31: =SUM(C31,F31,I31,L31,O31,R31,U31,X31) -> 0 | AC31: =SUM(D31,G31,J31,M31,P31,S31,V31,Y31) -> 0
D32: =B32*C32 -> 0 | E32: ='Break Down Per Community'!C7 -> 0 | F32: ='Break Down Per Community'!D7 -> 0 | G32: ='Break Down Per Community'!E7 -> 0 | H32: ='Break Down Per Community'!C7 -> 0 | I32: ='Break Down Per Community'!D7 -> 0 | J32: ='Break Down Per Community'!E7 -> 0 | K32: ='Break Down Per Community'!C7 -> 0 | L32: ='Break Down Per Community'!D7 -> 0 | M32: ='Break Down Per Community'!E7 -> 0 | N32: ='Break Down Per Community'!C7 -> 0 | O32: ='Break Down Per Community'!D7 -> 0 | P32: ='Break Down Per Community'!E7 -> 0 | Q32: ='Break Down Per Community'!C7 -> 0 | R32: ='Break Down Per Community'!D7 -> 0 | S32: ='Break Down Per Community'!E7 -> 0 | T32: ='Break Down Per Community'!C7 -> 0 | U32: ='Break Down Per Community'!D7 -> 0 | V32: ='Break Down Per Community'!E7 -> 0 | W32: =T32 -> 0 | X32: =U32 -> 0 | Y32: =V32 -> 0 | AA32: =SUM(B32,E32,H32,K32,N32,Q32,T32,W32) -> 0 | AB32: =SUM(C32,F32,I32,L32,O32,R32,U32,X32) -> 0 | AC32: =SUM(D32,G32,J32,M32,P32,S32,V32,Y32) -> 0
D33: =B33*C33 -> 0 | E33: ='Break Down Per Community'!C8 -> 0 | F33: ='Break Down Per Community'!D8 -> 0 | G33: ='Break Down Per Community'!E8 -> 0 | H33: ='Break Down Per Community'!C8 -> 0 | I33: ='Break Down Per Community'!D8 -> 0 | J33: ='Break Down Per Community'!E8 -> 0 | K33: ='Break Down Per Community'!C8 -> 0 | L33: ='Break Down Per Community'!D8 -> 0 | M33: ='Break Down Per Community'!E8 -> 0 | N33: ='Break Down Per Community'!C8 -> 0 | O33: ='Break Down Per Community'!D8 -> 0 | P33: ='Break Down Per Community'!E8 -> 0 | Q33: ='Break Down Per Community'!C8 -> 0 | R33: ='Break Down Per Community'!D8 -> 0 | S33: ='Break Down Per Community'!E8 -> 0 | T33: ='Break Down Per Community'!C8 -> 0 | U33: ='Break Down Per Community'!D8 -> 0 | V33: ='Break Down Per Community'!E8 -> 0 | W33: =T33 -> 0 | X33: =U33 -> 0 | Y33: =V33 -> 0 | AA33: =SUM(B33,E33,H33,K33,N33,Q33,T33,W33) -> 0 | AB33: =SUM(C33,F33,I33,L33,O33,R33,U33,X33) -> 0 | AC33: =SUM(D33,G33,J33,M33,P33,S33,V33,Y33) -> 0
D34: =B34*C34 -> 0 | E34: ='Break Down Per Community'!C9 -> 0 | F34: ='Break Down Per Community'!D9 -> 0 | G34: ='Break Down Per Community'!E9 -> 0 | H34: ='Break Down Per Community'!C9 -> 0 | I34: ='Break Down Per Community'!D9 -> 0 | J34: ='Break Down Per Community'!E9 -> 0 | K34: ='Break Down Per Community'!C9 -> 0 | L34: ='Break Down Per Community'!D9 -> 0 | M34: ='Break Down Per Community'!E9 -> 0 | N34: ='Break Down Per Community'!C9 -> 0 | O34: ='Break Down Per Community'!D9 -> 0 | P34: ='Break Down Per Community'!E9 -> 0 | Q34: ='Break Down Per Community'!C9 -> 0 | R34: ='Break Down Per Community'!D9 -> 0 | S34: ='Break Down Per Community'!E9 -> 0 | T34: ='Break Down Per Community'!C9 -> 0 | U34: ='Break Down Per Community'!D9 -> 0 | V34: ='Break Down Per Community'!E9 -> 0 | W34: =T34 -> 0 | X34: =U34 -> 0 | Y34: =V34 -> 0 | AA34: =SUM(B34,E34,H34,K34,N34,Q34,T34,W34) -> 0 | AB34: =SUM(C34,F34,I34,L34,O34,R34,U34,X34) -> 0 | AC34: =SUM(D34,G34,J34,M34,P34,S34,V34,Y34) -> 0
D35: =B35*C35 -> 0 | E35: ='Break Down Per Community'!C10 -> 0 | F35: ='Break Down Per Community'!D10 -> 0 | G35: ='Break Down Per Community'!E10 -> 0 | H35: ='Break Down Per Community'!C10 -> 0 | I35: ='Break Down Per Community'!D10 -> 0 | J35: ='Break Down Per Community'!E10 -> 0 | K35: ='Break Down Per Community'!C10 -> 0 | L35: ='Break Down Per Community'!D10 -> 0 | M35: ='Break Down Per Community'!E10 -> 0 | N35: ='Break Down Per Community'!C10 -> 0 | O35: ='Break Down Per Community'!D10 -> 0 | P35: ='Break Down Per Community'!E10 -> 0 | Q35: ='Break Down Per Community'!C10 -> 0 | R35: ='Break Down Per Community'!D10 -> 0 | S35: ='Break Down Per Community'!E10 -> 0 | T35: ='Break Down Per Community'!C10 -> 0 | U35: ='Break Down Per Community'!D10 -> 0 | V35: ='Break Down Per Community'!E10 -> 0 | W35: =T35 -> 0 | X35: =U35 -> 0 | Y35: =V35 -> 0 | AA35: =SUM(B35,E35,H35,K35,N35,Q35,T35,W35) -> 0 | AB35: =SUM(C35,F35,I35,L35,O35,R35,U35,X35) -> 0 | AC35: =SUM(D35,G35,J35,M35,P35,S35,V35,Y35) -> 0
A36: ="Total "&A27 -> Total Personnel Expenses | B36: =SUM(B28:B35) -> 170000 | C36: =SUM(C28:C35) -> 8 | D36: =SUM(D28:D35) -> 420000 | E36: =SUM(E28:E35) -> 170000 | F36: =SUM(F28:F35) -> 8 | G36: =SUM(G28:G35) -> 420000 | H36: =SUM(H28:H35) -> 170000 | I36: =SUM(I28:I35) -> 8 | ... Y36: =SUM(Y28:Y35) -> 420000 | AA36: =SUM(AA28:AA35) -> 1360000 | AB36: =SUM(C36,F36,I36,L36,IF($J$7=5,O36,0)) -> 32 | AC36: =SUM(AC28:AC35) -> 3360000
A38: ='Total '!B8 -> Equipment and Supplies | B38: =$B$11 -> Cost | C38: =$C$11 -> Frequency | D38: =$D$11 -> Total | E38: =$E$11 -> Cost | F38: =$F$11 -> Frequency | G38: =$G$11 -> Total | H38: =$H$11 -> Cost | I38: =$I$11 -> Frequency | J38: =$J$11 -> Total | K38: =$K$11 -> Cost | L38: =$L$11 -> Frequency | M38: =$M$11 -> Total | N38: =$K$11 -> Cost | O38: =$L$11 -> Frequency | P38: =$M$11 -> Total | Q38: =$H$11 -> Cost | R38: =$I$11 -> Frequency | S38: =$J$11 -> Total | T38: =$K$11 -> Cost | U38: =$L$11 -> Frequency | V38: =$M$11 -> Total | W38: =$K$11 -> Cost | X38: =$L$11 -> Frequency | Y38: =$M$11 -> Total | AA38: =$AA$11 -> Cost | AB38: =$AB$11 -> Frequency | AC38: =$AC$11 -> Total
A39: ='Break Down Per Community'!B14 -> Procurement for HPV Sampling | B39: ='Break Down Per Community'!C14 -> 1500 | C39: ='Break Down Per Community'!D14 -> 2000 | D39: =B39*C39 -> 3000000 | E39: =B39 -> 1500 | F39: =C39 -> 2000 | G39: =D39 -> 3000000 | H39: =E39 -> 1500 | I39: =F39 -> 2000 | J39: =G39 -> 3000000 | K39: =H39 -> 1500 | L39: =I39 -> 2000 | ... Y39: =V39 -> 3000000 | AA39: =SUM(B39,E39,H39,K39,N39,Q39,T39,W39) -> 12000 | AB39: =SUM(C39,F39,I39,L39,O39,R39,U39,X39) -> 16000 | AC39: =SUM(D39,G39,J39,M39,P39,S39,V39,Y39) -> 24000000
A40: ='Break Down Per Community'!B15 -> Labotory Analysis | B40: ='Break Down Per Community'!C15 -> 7822.5 | C40: ='Break Down Per Community'!D15 -> 2000 | D40: =B40*C40 -> 15645000 | E40: =B40 -> 7822.5 | F40: =C40 -> 2000 | G40: =D40 -> 15645000 | H40: =E40 -> 7822.5 | I40: =F40 -> 2000 | J40: =G40 -> 15645000 | K40: =H40 -> 7822.5 | L40: =I40 -> 2000 | ... Y40: =V40 -> 15645000 | AA40: =SUM(B40,E40,H40,K40,N40,Q40,T40,W40) -> 62580 | AB40: =SUM(C40,F40,I40,L40,O40,R40,U40,X40) -> 16000 | AC40: =SUM(D40,G40,J40,M40,P40,S40,V40,Y40) -> 125160000
A41: ='Break Down Per Community'!B16 -> Gynescope | B41: ='Break Down Per Community'!C16 -> 11250 | C41: ='Break Down Per Community'!D16 -> 2000 | D41: =B41*C41 -> 22500000 | E41: =B41 -> 11250 | F41: =C41 -> 2000 | G41: =D41 -> 22500000 | H41: =E41 -> 11250 | I41: =F41 -> 2000 | J41: =G41 -> 22500000 | K41: =H41 -> 11250 | L41: =I41 -> 2000 | ... Y41: =V41 -> 22500000 | AA41: =SUM(B41,E41,H41,K41,N41,Q41,T41,W41) -> 90000 | AB41: =SUM(C41,F41,I41,L41,O41,R41,U41,X41) -> 16000 | AC41: =SUM(D41,G41,J41,M41,P41,S41,V41,Y41) -> 180000000
A42: ='Break Down Per Community'!B17 -> Medical Supply and consumables | B42: ='Break Down Per Community'!C17 -> 2250 | C42: ='Break Down Per Community'!D17 -> 2000 | D42: =B42*C42 -> 4500000 | E42: =B42 -> 2250 | F42: =C42 -> 2000 | G42: =D42 -> 4500000 | H42: =E42 -> 2250 | I42: =F42 -> 2000 | J42: =G42 -> 4500000 | K42: =H42 -> 2250 | L42: =I42 -> 2000 | ... Y42: =V42 -> 4500000 | AA42: =SUM(B42,E42,H42,K42,N42,Q42,T42,W42) -> 18000 | AB42: =SUM(C42,F42,I42,L42,O42,R42,U42,X42) -> 16000 | AC42: =SUM(D42,G42,J42,M42,P42,S42,V42,Y42) -> 36000000
D43: =B43*C43 -> 0 | E43: =B43 -> 0 | F43: =C43 -> 0 | G43: =D43 -> 0 | H43: =E43 -> 0 | I43: =F43 -> 0 | J43: =G43 -> 0 | K43: =H43 -> 0 | L43: =I43 -> 0 | ... Y43: =V43 -> 0 | AA43: =SUM(B43,E43,H43,K43,N43,Q43,T43,W43) -> 0 | AB43: =SUM(C43,F43,I43,L43,O43,R43,U43,X43) -> 0 | AC43: =SUM(D43,G43,J43,M43,P43,S43,V43,Y43) -> 0
D44: =B44*C44 -> 0 | E44: =B44 -> 0 | F44: =C44 -> 0 | G44: =D44 -> 0 | H44: =E44 -> 0 | I44: =F44 -> 0 | J44: =G44 -> 0 | K44: =H44 -> 0 | L44: =I44 -> 0 | ... Y44: =V44 -> 0 | AA44: =SUM(B44,E44,H44,K44,N44,Q44,T44,W44) -> 0 | AB44: =SUM(C44,F44,I44,L44,O44,R44,U44,X44) -> 0 | AC44: =SUM(D44,G44,J44,M44,P44,S44,V44,Y44) -> 0
A45: ="Total "&A38 -> Total Equipment and Supplies | B45: =SUM(B39:B44) -> 22822.5 | C45: =SUM(C39:C44) -> 8000 | D45: =SUM(D39:D44) -> 45645000 | E45: =SUM(E39:E44) -> 22822.5 | F45: =SUM(F39:F44) -> 8000 | G45: =SUM(G39:G44) -> 45645000 | H45: =SUM(H39:H44) -> 22822.5 | I45: =SUM(I39:I44) -> 8000 | ... Y45: =SUM(Y39:Y44) -> 45645000 | AA45: =SUM(AA39:AA44) -> 182580 | AB45: =SUM(C45,F45,I45,L45,IF($J$7=5,O45,0)) -> 32000 | AC45: =SUM(AC39:AC44) -> 365160000
A47: ='Total '!B9 -> Training and Educaton | B47: =$B$11 -> Cost | C47: =$C$11 -> Frequency | D47: =$D$11 -> Total | E47: =$E$11 -> Cost | F47: =$F$11 -> Frequency | G47: =$G$11 -> Total | H47: =$H$11 -> Cost | I47: =$I$11 -> Frequency | J47: =J38 -> Total | K47: =$K$11 -> Cost | L47: =$L$11 -> Frequency | M47: =M38 -> Total | N47: =$K$11 -> Cost | O47: =$L$11 -> Frequency | P47: =P38 -> Total | Q47: =$H$11 -> Cost | R47: =$I$11 -> Frequency | S47: =S38 -> Total | T47: =$K$11 -> Cost | U47: =$L$11 -> Frequency | V47: =V38 -> Total | W47: =$K$11 -> Cost | X47: =$L$11 -> Frequency | Y47: =Y38 -> Total | AA47: =$AA$11 -> Cost | AB47: =$AB$11 -> Frequency | AC47: =$AC$11 -> Total
A48: ='Break Down Per Community'!B23 -> Training Programs | B48: ='Break Down Per Community'!C23 -> 570000 | C48: ='Break Down Per Community'!D23 -> 1 | D48: =B48*C48 -> 570000 | E48: =B48 -> 570000 | F48: =C48 -> 1 | G48: =D48 -> 570000 | H48: =E48 -> 570000 | I48: =F48 -> 1 | J48: =G48 -> 570000 | K48: =H48 -> 570000 | L48: =I48 -> 1 | ... Y48: =V48 -> 570000 | AA48: =SUM(B48,E48,H48,K48,N48,Q48,T48,W48) -> 4560000 | AB48: =SUM(C48,F48,I48,L48,O48,R48,U48,X48) -> 8 | AC48: =SUM(D48,G48,J48,M48,P48,S48,V48,Y48) -> 4560000
A49: ='Break Down Per Community'!B24 -> Education Materials | B49: ='Break Down Per Community'!C24 -> 0 | C49: ='Break Down Per Community'!D24 -> 1 | D49: =B49*C49 -> 0 | E49: =B49 -> 0 | F49: =C49 -> 1 | G49: =D49 -> 0 | H49: =E49 -> 0 | I49: =F49 -> 1 | J49: =G49 -> 0 | K49: =H49 -> 0 | L49: =I49 -> 1 | ... Y49: =V49 -> 0 | AA49: =SUM(B49,E49,H49,K49,N49,Q49,T49,W49) -> 0 | AB49: =SUM(C49,F49,I49,L49,O49,R49,U49,X49) -> 8 | AC49: =SUM(D49,G49,J49,M49,P49,S49,V49,Y49) -> 0
D50: =B50*C50 -> 0 | E50: =B50 -> 0 | F50: =C50 -> 0 | G50: =D50 -> 0 | H50: =E50 -> 0 | I50: =F50 -> 0 | J50: =G50 -> 0 | K50: =H50 -> 0 | L50: =I50 -> 0 | ... Y50: =V50 -> 0 | AA50: =SUM(B50,E50,H50,K50,N50,Q50,T50,W50) -> 0 | AB50: =SUM(C50,F50,I50,L50,O50,R50,U50,X50) -> 0 | AC50: =SUM(D50,G50,J50,M50,P50,S50,V50,Y50) -> 0
D51: =B51*C51 -> 0 | E51: =B51 -> 0 | F51: =C51 -> 0 | G51: =D51 -> 0 | H51: =E51 -> 0 | I51: =F51 -> 0 | J51: =G51 -> 0 | K51: =H51 -> 0 | L51: =I51 -> 0 | ... Y51: =V51 -> 0 | AA51: =SUM(B51,E51,H51,K51,N51,Q51,T51,W51) -> 0 | AB51: =SUM(C51,F51,I51,L51,O51,R51,U51,X51) -> 0 | AC51: =SUM(D51,G51,J51,M51,P51,S51,V51,Y51) -> 0
...
