Workbook

Sheet Summary
B12: Description | C12: Total Inflow | D12: Total Outflow (Expenses ) | E12: Balance
C14: N | D14: N | E14: N
B15: Income | C15: 0 | E15: =C15-D15 -> 0
B16: Peramare Medical Bank | C16: 150000000 | D16: ='Bank Schedule__1__'!H592-'Bank Schedule__1__'!G15-'Bank Schedule__1__'!H58 -> 78588749 | E16: =C16-D16 -> 71411251
B17: Peramare Medical Petty Cash | C17: 0 | D17: ='Cash-In-Hand Schedule_'!H590 -> 129000 | E17: =C17-D17 -> -129000
B18: Labell | C18: 112000000 | D18: ='Lanbell Lab'!G590 -> 97502100 | E18: =C18-D18 -> 14497900
B19: Peramare Ghana | C19: 133000000 | D19: ='Peramare Ghana'!G590 -> 0 | E19: =C19-D19 -> 133000000
B20: Others | C20: 0 | D20: =Others!G73 -> 98875916 | E20: =C20-D20 -> -98875916
B21: Current Balance | C21: =SUM(C12:C20) -> 395000000 | D21: =SUM(D12:D20) -> 2.7509576e+08 | E21: =C21-D21 -> 1.1990424e+08

Sheet Bank Schedule__1__
B10: Bank Analysis Schedule
J11: Inflow Breakdown | P11: Outflow Breakdown
B12: Date | C12: Description | D12: Transaction Categorisation | E12: Voucher Number | F12: User Unit/ Department | G12: Total Inflow | H12: Total Outflow (Expenses ) | I12: Balance | P12: Assets | S12: Overheads & Salary | AM12: Others
J13: Directors/ Shareholders Contribution | K13: Revenue | L13: Reversal | M13: Interest | N13: Advance Refund | O13: Intra Bank Transfer | P13: Office Equipment | Q13: Funiture and Fittings | R13: Motor Vehicle | S13: Repairs and Maintenance | T13: Transportation | U13: Travel | V13: Staff Welfare | W13: Security and cleaning services | X13: Volunteer Stipend | Y13: Staff salary and Allowance | Z13: Professional Fees | AA13: Internet & Telecommunication | AB13: Stationary & Office Suplies | AC13: Registration, Fees and Dues | AD13: Petty cash | AE13: Marketing and Advertisement | AF13: Hotel Accommodation | AG13: Fuel & lubricant | AH13: Tax | AI13: Training and Development | AJ13: Utilities | AK13: Product logistics | AL13: Bank Charges | AM13: Intra Bank Transfer | AN13: Reversal
G14: N | H14: N | I14: N | J14: N | K14: N | L14: N | M14: N | N14: N | O14: N | P14: N | Q14: N | R14: N | S14: N | T14: N | V14: N | W14: N | X14: N | Y14: N | Z14: N | AA14: N | AB14: N | AC14: N | AD14: N | AE14: N | AF14: N | AG14: N | AH14: N | AI14: N | AJ14: N | AL14: N | AM14: N | AN14: N
C15: Beginning Balance | G15: 6578462 | I15: =G15-H15 -> 6578462
B16: 44805 | C16: Electricity bill | D16: Utilities | E16: PV/0001 | F16: Admin | G16: 0 | H16: 50000 | I16: =I15+G16-H16 -> 6528462 | J16: 0 | P16: =IF($D16=P$13,$H16, 0) -> 0 | Q16: =IF($D16=Q$13,$H16, 0) -> 0 | R16: =IF($D16=R$13,$H16, 0) -> 0 | S16: =IF($D16=S$13,$H16, 0) -> 0 | T16: =IF($D16=T$13,$H16, 0) -> 0 | U16: =IF($D16=U$13,$H16, 0) -> 0 | V16: =IF($D16=V$13,$H16, 0) -> 0 | W16: =IF($D16=W$13,$H16, 0) -> 0 | ... AN16: =IF($D16=AN$13,$H16, 0) -> 0
B17: 44811 | C17: Shipping cost for illumigyn genescope | D17: Product logistics | E17: PV/0002 | F17: Logistics | H17: 58500 | I17: =I16+G17-H17 -> 6469962 | P17: =IF($D17=P$13,$H17, 0) -> 0 | Q17: =IF($D17=Q$13,$H17, 0) -> 0 | R17: =IF($D17=R$13,$H17, 0) -> 0 | S17: =IF($D17=S$13,$H17, 0) -> 0 | T17: =IF($D17=T$13,$H17, 0) -> 0 | U17: =IF($D17=U$13,$H17, 0) -> 0 | V17: =IF($D17=V$13,$H17, 0) -> 0 | W17: =IF($D17=W$13,$H17, 0) -> 0 | ... AN17: =IF($D17=AN$13,$H17, 0) -> 0
B18: 44812 | C18: Marriage allowance | D18: Staff Welfare | E18: PV/0003 | F18: Admin | H18: 50000 | I18: =I17+G18-H18 -> 6419962 | P18: =IF($D18=P$13,$H18, 0) -> 0 | Q18: =IF($D18=Q$13,$H18, 0) -> 0 | R18: =IF($D18=R$13,$H18, 0) -> 0 | S18: =IF($D18=S$13,$H18, 0) -> 0 | T18: =IF($D18=T$13,$H18, 0) -> 0 | U18: =IF($D18=U$13,$H18, 0) -> 0 | V18: =IF($D18=V$13,$H18, 0) -> 50000 | W18: =IF($D18=W$13,$H18, 0) -> 0 | ... AN18: =IF($D18=AN$13,$H18, 0) -> 0
B19: 44812 | C19: Childbirth allowance | D19: Staff Welfare | E19: PV/0003 | F19: Admin | H19: 50000 | I19: =I18+G19-H19 -> 6369962 | P19: =IF($D19=P$13,$H19, 0) -> 0 | Q19: =IF($D19=Q$13,$H19, 0) -> 0 | R19: =IF($D19=R$13,$H19, 0) -> 0 | S19: =IF($D19=S$13,$H19, 0) -> 0 | T19: =IF($D19=T$13,$H19, 0) -> 0 | U19: =IF($D19=U$13,$H19, 0) -> 0 | V19: =IF($D19=V$13,$H19, 0) -> 50000 | W19: =IF($D19=W$13,$H19, 0) -> 0 | ... AN19: =IF($D19=AN$13,$H19, 0) -> 0
B20: 44812 | C20: Repairs and Maintenance: Motor vehicle | D20: Repairs and Maintenance | E20: PV/0004 | F20: Admin | H20: 30000 | I20: =I19+G20-H20 -> 6339962 | P20: =IF($D20=P$13,$H20, 0) -> 0 | Q20: =IF($D20=Q$13,$H20, 0) -> 0 | R20: =IF($D20=R$13,$H20, 0) -> 0 | S20: =IF($D20=S$13,$H20, 0) -> 30000 | T20: =IF($D20=T$13,$H20, 0) -> 0 | U20: =IF($D20=U$13,$H20, 0) -> 0 | V20: =IF($D20=V$13,$H20, 0) -> 0 | W20: =IF($D20=W$13,$H20, 0) -> 0 | ... AN20: =IF($D20=AN$13,$H20, 0) -> 0
B21: 44812 | C21: Airplane Tickets and accommodation for guests | D21: Transportation | E21: PV/0005 | F21: Sales Department | H21: 130000 | I21: =I20+G21-H21 -> 6209962 | T21: 307000 | U21: 307000
B22: 44812 | C22: Airplane Tickets and accommodation Refunded From Staff | D22: Transportation | F22: Sales Department | G22: 4200 | H22: 0 | I22: =I21+G22-H22 -> 6214162 | AC22: 10000
B23: 44812 | C23: Airplane Tickets and accommodation for guests | D23: Transportation | E23: PV/0006 | F23: Sales Department | H23: 207000 | I23: =I22+G23-H23 -> 6007162 | T23: 207000 | U23: 207000
B24: 44813 | C24: Nanox Importation license | D24: Registration, Fees and Dues | E24: PV/0007 | F24: Logistics | H24: 100000 | I24: =I23+G24-H24 -> 5907162 | P24: =IF($D24=P$13,$H24, 0) -> 0 | Q24: =IF($D24=Q$13,$H24, 0) -> 0 | R24: =IF($D24=R$13,$H24, 0) -> 0 | S24: =IF($D24=S$13,$H24, 0) -> 0 | T24: =IF($D24=T$13,$H24, 0) -> 0 | U24: =IF($D24=U$13,$H24, 0) -> 0 | V24: =IF($D24=V$13,$H24, 0) -> 0 | W24: =IF($D24=W$13,$H24, 0) -> 0 | ... AN24: =IF($D24=AN$13,$H24, 0) -> 0
B25: 44816 | C25: Maintenance and repairs: Laptop Reimbursement | D25: Repairs and Maintenance | E25: PV/0008 | F25: Admin | H25: 80000 | I25: =I24+G25-H25 -> 5827162 | P25: =IF($D25=P$13,$H25, 0) -> 0 | Q25: =IF($D25=Q$13,$H25, 0) -> 0 | R25: =IF($D25=R$13,$H25, 0) -> 0 | S25: =IF($D25=S$13,$H25, 0) -> 80000 | T25: =IF($D25=T$13,$H25, 0) -> 0 | U25: =IF($D25=U$13,$H25, 0) -> 0 | V25: =IF($D25=V$13,$H25, 0) -> 0 | W25: =IF($D25=W$13,$H25, 0) -> 0 | ... AN25: =IF($D25=AN$13,$H25, 0) -> 0
B26: 44816 | C26: Maintenance and repairs: AC installations | D26: Repairs and Maintenance | E26: PV/0009 | F26: Admin | H26: 175000 | I26: =I25+G26-H26 -> 5652162 | P26: =IF($D26=P$13,$H26, 0) -> 0 | Q26: =IF($D26=Q$13,$H26, 0) -> 0 | R26: =IF($D26=R$13,$H26, 0) -> 0 | S26: =IF($D26=S$13,$H26, 0) -> 175000 | T26: =IF($D26=T$13,$H26, 0) -> 0 | U26: =IF($D26=U$13,$H26, 0) -> 0 | V26: =IF($D26=V$13,$H26, 0) -> 0 | W26: =IF($D26=W$13,$H26, 0) -> 0 | ... AN26: =IF($D26=AN$13,$H26, 0) -> 0
B27: 44816 | C27: Electricity bill | D27: Utilities | E27: PV/0010 | F27: Admin | H27: 50000 | I27: =I26+G27-H27 -> 5602162 | P27: =IF($D27=P$13,$H27, 0) -> 0 | Q27: =IF($D27=Q$13,$H27, 0) -> 0 | R27: =IF($D27=R$13,$H27, 0) -> 0 | S27: =IF($D27=S$13,$H27, 0) -> 0 | T27: =IF($D27=T$13,$H27, 0) -> 0 | U27: =IF($D27=U$13,$H27, 0) -> 0 | V27: =IF($D27=V$13,$H27, 0) -> 0 | W27: =IF($D27=W$13,$H27, 0) -> 0 | ... AN27: =IF($D27=AN$13,$H27, 0) -> 0
B28: 44816 | C28: Payment for the transfer and activation of domain | D28: Internet and telecommunication | E28: PV/0011 | F28: IT | H28: 20000 | I28: =I27+G28-H28 -> 5582162 | AA28: 20000
B29: 44818 | C29: Web hosting subscription and email service | D29: Internet and telecommunication | E29: PV/0012 | F29: IT | H29: 71000 | I29: =I28+G29-H29 -> 5511162 | AA29: 71000
B30: 44818 | C30: Staff Travel Expenses | D30: Training and Development | E30: PV/0013 | F30: Sales Department | H30: 308000 | I30: =I29+G30-H30 -> 5203162 | AI30: 308000
B31: 44819 | C31: Office Supplies | D31: Stationary & Office Suplies | E31: PV/0014 | F31: Admin | H31: 212000 | I31: =I30+G31-H31 -> 4991162 | P31: =IF($D31=P$13,$H31, 0) -> 0 | Q31: =IF($D31=Q$13,$H31, 0) -> 0 | R31: =IF($D31=R$13,$H31, 0) -> 0 | S31: =IF($D31=S$13,$H31, 0) -> 0 | T31: =IF($D31=T$13,$H31, 0) -> 0 | U31: =IF($D31=U$13,$H31, 0) -> 0 | V31: =IF($D31=V$13,$H31, 0) -> 0 | W31: =IF($D31=W$13,$H31, 0) -> 0 | ... AN31: =IF($D31=AN$13,$H31, 0) -> 0
B32: 44819 | C32: Payment for Business Cards | D32: Printing | E32: PV/0015 | F32: Sales Department | H32: 40000 | I32: =I31+G32-H32 -> 4951162
B33: 44819 | C33: Payment for shipping gynescopes | D33: Product logistics | E33: PV/0016 | F33: Logistics | H33: 516361.63 | I33: =I32+G33-H33 -> 4434800.4 | P33: =IF($D33=P$13,$H33, 0) -> 0 | Q33: =IF($D33=Q$13,$H33, 0) -> 0 | R33: =IF($D33=R$13,$H33, 0) -> 0 | S33: =IF($D33=S$13,$H33, 0) -> 0 | T33: =IF($D33=T$13,$H33, 0) -> 0 | U33: =IF($D33=U$13,$H33, 0) -> 0 | V33: =IF($D33=V$13,$H33, 0) -> 0 | W33: =IF($D33=W$13,$H33, 0) -> 0 | ... AN33: =IF($D33=AN$13,$H33, 0) -> 0
B34: 44819 | C34: Printing of marketing products: brochures | D34: Printing | E34: PV/0017 | F34: Sales Department | H34: 17500 | I34: =I33+G34-H34 -> 4417300.4
B35: 44820 | C35: Repairs and Maintenance: Electrical Appliances | D35: Repairs and Maintenance | E35: PV/0018 | F35: Admin | H35: 35700 | I35: =I34+G35-H35 -> 4381600.4 | P35: =IF($D35=P$13,$H35, 0) -> 0 | Q35: =IF($D35=Q$13,$H35, 0) -> 0 | R35: =IF($D35=R$13,$H35, 0) -> 0 | S35: =IF($D35=S$13,$H35, 0) -> 35700 | T35: =IF($D35=T$13,$H35, 0) -> 0 | U35: =IF($D35=U$13,$H35, 0) -> 0 | V35: =IF($D35=V$13,$H35, 0) -> 0 | W35: =IF($D35=W$13,$H35, 0) -> 0 | ... AN35: =IF($D35=AN$13,$H35, 0) -> 0
B36: 44823 | C36: Payment for SCMUL | D36: Registration, Fees and Dues | E36: PV/0019 | F36: Admin | H36: 80000 | I36: =I35+G36-H36 -> 4301600.4 | P36: =IF($D36=P$13,$H36, 0) -> 0 | Q36: =IF($D36=Q$13,$H36, 0) -> 0 | R36: =IF($D36=R$13,$H36, 0) -> 0 | S36: =IF($D36=S$13,$H36, 0) -> 0 | T36: =IF($D36=T$13,$H36, 0) -> 0 | U36: =IF($D36=U$13,$H36, 0) -> 0 | V36: =IF($D36=V$13,$H36, 0) -> 0 | W36: =IF($D36=W$13,$H36, 0) -> 0 | ... AN36: =IF($D36=AN$13,$H36, 0) -> 0
B37: 44824 | C37: Office supplies | D37: Office equipment | E37: PV/0020 | F37: Admin | H37: 7500 | I37: =I36+G37-H37 -> 4294100.4 | P37: =IF($D37=P$13,$H37, 0) -> 7500 | Q37: =IF($D37=Q$13,$H37, 0) -> 0 | R37: =IF($D37=R$13,$H37, 0) -> 0 | S37: =IF($D37=S$13,$H37, 0) -> 0 | T37: =IF($D37=T$13,$H37, 0) -> 0 | U37: =IF($D37=U$13,$H37, 0) -> 0 | V37: =IF($D37=V$13,$H37, 0) -> 0 | W37: =IF($D37=W$13,$H37, 0) -> 0 | ... AN37: =IF($D37=AN$13,$H37, 0) -> 0
B38: 44826 | C38: Repairs and Maintenance: Electrical Appliances | D38: Repairs and Maintenance | E38: PV/0021 | F38: Admin | H38: 14000 | I38: =I37+G38-H38 -> 4280100.4 | P38: =IF($D38=P$13,$H38, 0) -> 0 | Q38: =IF($D38=Q$13,$H38, 0) -> 0 | R38: =IF($D38=R$13,$H38, 0) -> 0 | S38: =IF($D38=S$13,$H38, 0) -> 14000 | T38: =IF($D38=T$13,$H38, 0) -> 0 | U38: =IF($D38=U$13,$H38, 0) -> 0 | V38: =IF($D38=V$13,$H38, 0) -> 0 | W38: =IF($D38=W$13,$H38, 0) -> 0 | ... AN38: =IF($D38=AN$13,$H38, 0) -> 0
B39: 44826 | C39: Salary For The Month of September | D39: Staff Salary and Allowance | E39: PV/0022 | F39: HR | H39: 3540000 | I39: =I38+G39-H39 -> 740100.37 | P39: =IF($D39=P$13,$H39, 0) -> 0 | Q39: =IF($D39=Q$13,$H39, 0) -> 0 | R39: =IF($D39=R$13,$H39, 0) -> 0 | S39: =IF($D39=S$13,$H39, 0) -> 0 | T39: =IF($D39=T$13,$H39, 0) -> 0 | U39: =IF($D39=U$13,$H39, 0) -> 0 | V39: =IF($D39=V$13,$H39, 0) -> 0 | W39: =IF($D39=W$13,$H39, 0) -> 0 | ... AN39: =IF($D39=AN$13,$H39, 0) -> 0
B40: 44826 | C40: Webcam and dungle | D40: Office equipment | E40: PV/0023 | F40: IT | H40: 28000 | I40: =I39+G40-H40 -> 712100.37
B41: 44827 | C41: Electricity bill | D41: Utilities | E41: PV/0024 | F41: Admin | H41: 50000 | I41: =I40+G41-H41 -> 662100.37 | P41: =IF($D41=P$13,$H41, 0) -> 0 | Q41: =IF($D41=Q$13,$H41, 0) -> 0 | R41: =IF($D41=R$13,$H41, 0) -> 0 | S41: =IF($D41=S$13,$H41, 0) -> 0 | T41: =IF($D41=T$13,$H41, 0) -> 0 | U41: =IF($D41=U$13,$H41, 0) -> 0 | V41: =IF($D41=V$13,$H41, 0) -> 0 | W41: =IF($D41=W$13,$H41, 0) -> 0 | ... AN41: =IF($D41=AN$13,$H41, 0) -> 0
B42: 44830 | C42: Repairs and Maintenance: Electrical Appliances | D42: Repairs and Maintenance | E42: PV/0025 | F42: Admin | H42: 139400 | I42: =I41+G42-H42 -> 522700.37 | P42: =IF($D42=P$13,$H42, 0) -> 0 | Q42: =IF($D42=Q$13,$H42, 0) -> 0 | R42: =IF($D42=R$13,$H42, 0) -> 0 | S42: =IF($D42=S$13,$H42, 0) -> 139400 | T42: =IF($D42=T$13,$H42, 0) -> 0 | U42: =IF($D42=U$13,$H42, 0) -> 0 | V42: =IF($D42=V$13,$H42, 0) -> 0 | W42: =IF($D42=W$13,$H42, 0) -> 0 | ... AN42: =IF($D42=AN$13,$H42, 0) -> 0
B43: 44832 | C43: Repairs and Maintenance: Plumbing | D43: Repairs and Maintenance | E43: PV/0026 | F43: Admin | H43: 14500 | I43: =I42+G43-H43 -> 508200.37 | P43: =IF($D43=P$13,$H43, 0) -> 0 | Q43: =IF($D43=Q$13,$H43, 0) -> 0 | R43: =IF($D43=R$13,$H43, 0) -> 0 | S43: =IF($D43=S$13,$H43, 0) -> 14500 | T43: =IF($D43=T$13,$H43, 0) -> 0 | U43: =IF($D43=U$13,$H43, 0) -> 0 | V43: =IF($D43=V$13,$H43, 0) -> 0 | W43: =IF($D43=W$13,$H43, 0) -> 0 | ... AN43: =IF($D43=AN$13,$H43, 0) -> 0
B44: 44833 | C44: Payment for Fire service registration | D44: Registration, Fees and Dues | E44: PV/0027 | F44: Admin | H44: 254000 | I44: =I43+G44-H44 -> 254200.37 | P44: =IF($D44=P$13,$H44, 0) -> 0 | Q44: =IF($D44=Q$13,$H44, 0) -> 0 | R44: =IF($D44=R$13,$H44, 0) -> 0 | S44: =IF($D44=S$13,$H44, 0) -> 0 | T44: =IF($D44=T$13,$H44, 0) -> 0 | U44: =IF($D44=U$13,$H44, 0) -> 0 | V44: =IF($D44=V$13,$H44, 0) -> 0 | W44: =IF($D44=W$13,$H44, 0) -> 0 | ... AN44: =IF($D44=AN$13,$H44, 0) -> 0
B45: 44833 | C45: Payment for the purchase of diesel | D45: Fuel & lubricant | E45: PV/0028 | F45: Admin | H45: 200000 | I45: =I44+G45-H45 -> 54200.37 | P45: =IF($D45=P$13,$H45, 0) -> 0 | Q45: =IF($D45=Q$13,$H45, 0) -> 0 | R45: =IF($D45=R$13,$H45, 0) -> 0 | S45: =IF($D45=S$13,$H45, 0) -> 0 | T45: =IF($D45=T$13,$H45, 0) -> 0 | U45: =IF($D45=U$13,$H45, 0) -> 0 | V45: =IF($D45=V$13,$H45, 0) -> 0 | W45: =IF($D45=W$13,$H45, 0) -> 0 | ... AN45: =IF($D45=AN$13,$H45, 0) -> 0
B46: 44839 | C46: Electricity bill | D46: Utilities | E46: PV/0029 | F46: Admin | H46: 50000 | I46: =I45+G46-H46 -> 4200.37 | P46: =IF($D46=P$13,$H46, 0) -> 0 | Q46: =IF($D46=Q$13,$H46, 0) -> 0 | R46: =IF($D46=R$13,$H46, 0) -> 0 | S46: =IF($D46=S$13,$H46, 0) -> 0 | T46: =IF($D46=T$13,$H46, 0) -> 0 | U46: =IF($D46=U$13,$H46, 0) -> 0 | V46: =IF($D46=V$13,$H46, 0) -> 0 | W46: =IF($D46=W$13,$H46, 0) -> 0 | ... AN46: =IF($D46=AN$13,$H46, 0) -> 0
B47: 44839 | C47: income | G47: 150000000 | I47: =I46+G47-H47 -> 1.500042e+08
B48: 44840 | C48: Staff Renumeration | D48: Staff Salary and allowance | E48: PV/0030 | F48: HR | H48: 150000 | I48: =I47+G48-H48 -> 1.498542e+08 | P48: =IF($D48=P$13,$H48, 0) -> 0 | Q48: =IF($D48=Q$13,$H48, 0) -> 0 | R48: =IF($D48=R$13,$H48, 0) -> 0 | S48: =IF($D48=S$13,$H48, 0) -> 0 | T48: =IF($D48=T$13,$H48, 0) -> 0 | U48: =IF($D48=U$13,$H48, 0) -> 0 | V48: =IF($D48=V$13,$H48, 0) -> 0 | W48: =IF($D48=W$13,$H48, 0) -> 0 | ... AN48: =IF($D48=AN$13,$H48, 0) -> 0
B49: 44840 | C49: Purchase of TVs | D49: Office equipment | E49: PV/0031 | F49: Admin | H49: 1994000 | I49: =I48+G49-H49 -> 1.478602e+08 | P49: =IF($D49=P$13,$H49, 0) -> 1994000 | Q49: =IF($D49=Q$13,$H49, 0) -> 0 | R49: =IF($D49=R$13,$H49, 0) -> 0 | S49: =IF($D49=S$13,$H49, 0) -> 0 | T49: =IF($D49=T$13,$H49, 0) -> 0 | U49: =IF($D49=U$13,$H49, 0) -> 0 | V49: =IF($D49=V$13,$H49, 0) -> 0 | W49: =IF($D49=W$13,$H49, 0) -> 0 | ... AN49: =IF($D49=AN$13,$H49, 0) -> 0
...

Sheet Lanbell Lab
B10: Bank Analysis Schedule
I11: Inflow Breakdown | O11: Outflow Breakdown
B12: Date | C12: Description | D12: Transaction Categorisation | E12: User Unit/ Department | F12: Total Inflow | G12: Total Outflow (Expenses ) | H12: Balance | O12: Assets | R12: Overheads & Salary | AK12: Others
I13: Directors/ Shareholders Contribution | J13: Revenue | K13: Reversal | L13: Interest | M13: Advance Refund | N13: Intra Bank Transfer | O13: Office Equipment | P13: Furnitures & Fittings | Q13: Motor Vehicle | R13: Repairs & Maintenance | S13: Transportation | T13: Staff Welfare, Medicals and Entertainment | U13: Security services | V13: Volunteer Stipend | W13: Staff salary & Allowance | X13: Professional Fees | Y13: Internet & Telecommunication | Z13: Stationery & office supplies | AA13: Registration, Fees and Dues | AB13: Petty cash | AC13: Marketing and Advertisement | AD13: Hotel Accommodation | AE13: Fuel & Lubricant | AF13: Tax | AG13: Training and Development | AH13: Utility | AI13: Product Logistics (Air, Sea, Rail and Land) | AJ13: Bank Charges | AK13: Intra Bank Transfer | AL13: Reversal
F14: N | G14: N | H14: N | I14: N | J14: N | K14: N | L14: N | M14: N | N14: N | O14: N | P14: N | Q14: N | R14: N | S14: N | T14: N | U14: N | V14: N | W14: N | X14: N | Y14: N | Z14: N | AA14: N | AB14: N | AC14: N | AD14: N | AE14: N | AF14: N | AG14: N | AH14: N | AJ14: N | AK14: N | AL14: N
B15: 44824 | C15: Income | F15: 112000000 | H15: =F15-G15 -> 112000000
C16: Lanbell | F16: 0 | G16: 36496350 | H16: =H15+F16-G16 -> 75503650 | AH16: 50000
C17: Lanbell | F17: 0 | G17: 20000000 | H17: =H16+F17-G17 -> 55503650 | AI17: 58500
C18: Lanbell | F18: 0 | G18: 20000000 | H18: =H17+F18-G18 -> 35503650
B19: 44887 | C19: Lanbell | F19: 0 | G19: 20000000 | H19: =H18+F19-G19 -> 15503650
C20: Consultattion fees | D20: 1350 | F20: 0 | G20: 1005750 | H20: =H19+F20-G20 -> 14497900
F21: 0 | H21: =H20+F21-G21 -> 14497900
F22: 0 | H22: =H21+F22-G22 -> 14497900
F23: 0 | H23: =H22+F23-G23 -> 14497900
F24: 0 | H24: =H23+F24-G24 -> 14497900
F25: 0 | H25: =H24+F25-G25 -> 14497900
F26: 0 | H26: =H25+F26-G26 -> 14497900
F27: 0 | H27: =H26+F27-G27 -> 14497900
F28: 0 | H28: =H27+F28-G28 -> 14497900
F29: 0 | H29: =H28+F29-G29 -> 14497900
F30: 0 | H30: =H29+F30-G30 -> 14497900
F31: 0 | H31: =H30+F31-G31 -> 14497900
F32: 0 | H32: =H31+F32-G32 -> 14497900
... F56: 0 | H56: =H55+F56-G56 -> 14497900
H57: =H56+F57-G57 -> 14497900
H58: =H57+F58-G58 -> 14497900
H59: =H58+F59-G59 -> 14497900
H60: =H59+F60-G60 -> 14497900
H61: =H60+F61-G61 -> 14497900
H62: =H61+F62-G62 -> 14497900
H63: =H62+F63-G63 -> 14497900
H64: =H63+F64-G64 -> 14497900
H65: =H64+F65-G65 -> 14497900
H66: =H65+F66-G66 -> 14497900
H67: =H66+F67-G67 -> 14497900
H68: =H67+F68-G68 -> 14497900
... H589: =H588+F589-G589 -> 14497900
F590: =SUM(F12:F589) -> 112000000 | G590: =SUM(G12:G589) -> 97502100 | I590: =SUM(I16:I589) -> 0 | J590: =SUM(J16:J589) -> 0 | K590: =SUM(K16:K589) -> 0 | L590: =SUM(L16:L589) -> 0 | M590: =SUM(M16:M589) -> 0 | N590: =SUM(N16:N589) -> 0 | O590: =SUM(O12:O589) -> 0 | P590: =SUM(P12:P589) -> 0 | Q590: =SUM(Q12:Q589) -> 0 | R590: =SUM(R12:R589) -> 0 | S590: =SUM(S12:S589) -> 0 | T590: =SUM(T12:T589) -> 0 | U590: =SUM(U12:U589) -> 0 | V590: =SUM(V12:V589) -> 0 | ... AH590: =SUM(AH12:AH589) -> 50000 | AJ590: =SUM(AJ12:AJ589) -> 0 | AL590: =SUM(AL12:AL589) -> 0

Sheet Others
B10: Bank Analysis Schedule
B12: Date | C12: Description | D12: Transaction Categorisation | E12: User Unit/ Department | F12: Total Inflow | G12: Total Outflow (Expenses ) | H12: Balance
F14: N | G14: N | H14: N
F15: 0 | G15: 0 | H15: =F15-G15 -> 0
C16: Hadiza September Salary | E16: Agro-Allied | F16: 0 | G16: 250000 | H16: =H15+F16-G16 -> -250000
C17: Aisha September Salary | E17: Agro-Allied | F17: 0 | G17: 250000 | H17: =H16+F17-G17 -> -500000
B18: 44829 | C18: Munadak Nig Limited | F18: 0 | G18: 3590000 | H18: =H17+F18-G18 -> -4090000
B19: 44839 | C19: Rubix Advisors Limited | E19: Rubix | F19: 0 | G19: 10000000 | H19: =H18+F19-G19 -> -14090000
B20: 44841 | C20: Nawa property | E20: Agro-Allied | F20: 0 | G20: 10416300 | H20: =H19+F20-G20 -> -24506300
B21: 44858 | C21: Aisha October Salary | E21: Agro-Allied | F21: 0 | G21: 250000 | H21: =H20+F21-G21 -> -24756300
B22: 44858 | C22: Hadiza October Salary | E22: Agro-Allied | F22: 0 | G22: 250000 | H22: =H21+F22-G22 -> -25006300
B23: 44858 | C23: Emmanuella October salary | F23: 0 | G23: 150000 | H23: =H22+F23-G23 -> -25156300
B24: 44858 | C24: Abdulmalik October salary | F24: 0 | G24: 150000 | H24: =H23+F24-G24 -> -25306300
C25: Walida Export promotions | F25: 0 | G25: 50000 | H25: =H24+F25-G25 -> -25356300
B26: 44887 | C26: HMO Fliers and Checklist | E26: HMO | F26: 0 | G26: 90000 | H26: =H25+F26-G26 -> -25446300
B27: 44887 | C27: Tchill (Agro Allied) | E27: Agro-Allied | F27: 0 | G27: 10000000 | H27: =H26+F27-G27 -> -35446300
B28: 44887 | C28: Zainab Nafdac Reimbursemt | F28: 0 | G28: 300000 | H28: =H27+F28-G28 -> -35746300
B29: 44887 | C29: Hadiza November Salary | E29: Agro-Allied | F29: 0 | G29: 250000 | H29: =H28+F29-G29 -> -35996300
B30: 44887 | C30: Aisha November Salary | E30: Agro-Allied | F30: 0 | G30: 250000 | H30: =H29+F30-G30 -> -36246300
B31: 44887 | C31: Emmanuella November salary | F31: 0 | G31: 150000 | H31: =H30+F31-G31 -> -36396300
B32: 44887 | C32: Abdulmalik November salary | F32: 0 | G32: 150000 | H32: =H31+F32-G32 -> -36546300
B33: 44887 | C33: Abdullahi Nabegu November Salary | F33: 0 | G33: 300000 | H33: =H32+F33-G33 -> -36846300
B34: 44887 | C34: Nura November Salary | F34: 0 | G34: 300000 | H34: =H33+F34-G34 -> -37146300
B35: 44887 | C35: Life Zone Pharmacy and stores | F35: 0 | G35: 10000000 | H35: =H34+F35-G35 -> -47146300
B36: 44887 | C36: Nafisa Ahmad Consultancy | E36: All round | F36: 0 | G36: 2000000 | H36: =H35+F36-G36 -> -49146300
B37: 44887 | C37: Basiru Salisu Consultancy | E37: HMO | F37: 0 | G37: 100000 | H37: =H36+F37-G37 -> -49246300
B38: 44889 | C38: Consultancy | E38: HMO | F38: 0 | G38: 300000 | H38: =H37+F38-G38 -> -49546300
B39: 44889 | C39: Crelio health subscription plan | E39: HMO | F39: 0 | G39: 1045000 | H39: =H38+F39-G39 -> -50591300
B40: 44889 | C40: Health care support systems | E40: HMO | F40: 0 | G40: 2000000 | H40: =H39+F40-G40 -> -52591300
B41: 44889 | C41: Acturial services | E41: HMO | F41: 0 | G41: 2553125 | H41: =H40+F41-G41 -> -55144425
B42: 44889 | C42: HMO Stipends | E42: HMO | F42: 0 | G42: 1300000 | H42: =H41+F42-G42 -> -56444425
B43: 44889 | C43: HMO office documents | E43: HMO | F43: 0 | G43: 170000 | H43: =H42+F43-G43 -> -56614425
B44: 44893 | C44: HMO feeding Allowance | E44: HMO | F44: 0 | G44: 125000 | H44: =H43+F44-G44 -> -56739425
B45: 44895 | C45: IT Subscription | E45: HMO | F45: 0 | G45: 130000 | H45: =H44+F45-G45 -> -56869425
B46: 44896 | C46: Legal Cinsultation fees | D46: 2500 | E46: Peramare Kenya | F46: 0 | G46: 1875000 | H46: =H45+F46-G46 -> -58744425
B47: 44901 | C47: A parcel for the MD | G47: 25000 | H47: =H46+F47-G47 -> -58769425
B48: 44904 | C48: HMO Tea Room | E48: HMO | G48: 42000 | H48: =H47+F48-G48 -> -58811425
B49: 44904 | C49: TV for HMO | E49: HMO | G49: 370000 | H49: =H48+F49-G49 -> -59181425
B50: 44904 | C50: Logistics for IT Sky Solutions Meeting | E50: HMO | G50: 26500 | H50: =H49+F50-G50 -> -59207925
B51: 44904 | C51: Development of Health Care Provider (HCP) Network | E51: HMO | G51: 4914525 | H51: =H50+F51-G51 -> -64122450
...

Sheet Peramare Ghana
B10: Bank Analysis Schedule
B12: Date | C12: Description | D12: Transaction Categorisation | E12: User Unit/ Department | F12: Total Inflow | G12: Total Outflow (Expenses ) | H12: Balance
F14: N | G14: N | H14: N
B15: 44824 | C15: Income | F15: 133000000 | H15: =F15-G15 -> 133000000
F16: 0 | H16: =H15+F16-G16 -> 133000000
F17: 0 | H17: =H16+F17-G17 -> 133000000
F18: 0 | H18: =H17+F18-G18 -> 133000000
F19: 0 | H19: =H18+F19-G19 -> 133000000
F20: 0 | H20: =H19+F20-G20 -> 133000000
F21: 0 | H21: =H20+F21-G21 -> 133000000
F22: 0 | H22: =H21+F22-G22 -> 133000000
F23: 0 | H23: =H22+F23-G23 -> 133000000
F24: 0 | H24: =H23+F24-G24 -> 133000000
F25: 0 | H25: =H24+F25-G25 -> 133000000
F26: 0 | H26: =H25+F26-G26 -> 133000000
F27: 0 | H27: =H26+F27-G27 -> 133000000
... F56: 0 | H56: =H55+F56-G56 -> 133000000
H57: =H56+F57-G57 -> 133000000
H58: =H57+F58-G58 -> 133000000
H59: =H58+F59-G59 -> 133000000
H60: =H59+F60-G60 -> 133000000
H61: =H60+F61-G61 -> 133000000
H62: =H61+F62-G62 -> 133000000
H63: =H62+F63-G63 -> 133000000
H64: =H63+F64-G64 -> 133000000
H65: =H64+F65-G65 -> 133000000
H66: =H65+F66-G66 -> 133000000
H67: =H66+F67-G67 -> 133000000
H68: =H67+F68-G68 -> 133000000
... H589: =H588+F589-G589 -> 133000000
F590: =SUM(F12:F589) -> 133000000 | G590: =SUM(G12:G589) -> 0

Sheet Other
B10: Bank Analysis Schedule
B12: Date | C12: Description | D12: Transaction Categorisation | E12: User Unit/ Department | F12: Total Inflow | G12: Total Outflow (Expenses ) | H12: Balance
F14: N | G14: N | H14: N
B15: 44829 | C15: Munadak Nig Limited | F15: 0 | G15: 3590000 | H15: -3590000
B16: 44839 | C16: Rubix Advisors Limited | E16: Rubix | F16: 0 | G16: 10000000 | H16: =H15+F16-G16 -> -13590000
B17: 44858 | C17: Emmanuella October salary | F17: 0 | G17: 150000 | H17: =H16+F17-G17 -> -13740000
B18: 44858 | C18: Abdulmalik October salary | F18: 0 | G18: 150000 | H18: =H17+F18-G18 -> -13890000
C19: Walida Export promotions | F19: 0 | G19: 50000 | H19: =H18+F19-G19 -> -13940000
B20: 44887 | C20: Zainab Nafdac Reimbursemt | F20: 0 | G20: 300000 | H20: =H19+F20-G20 -> -14240000
B21: 44887 | C21: Emmanuella November salary | F21: 0 | G21: 150000 | H21: =H20+F21-G21 -> -14390000
B22: 44887 | C22: Abdulmalik November salary | F22: 0 | G22: 150000 | H22: =H21+F22-G22 -> -14540000
B23: 44887 | C23: Abdullahi Nabegu November Salary | F23: 0 | G23: 300000 | H23: =H22+F23-G23 -> -14840000
B24: 44887 | C24: Nura November Salary | F24: 0 | G24: 300000 | H24: =H23+F24-G24 -> -15140000
B25: 44887 | C25: Life Zone Pharmacy and stores | F25: 0 | G25: 10000000 | H25: =H24+F25-G25 -> -25140000
B26: 44887 | C26: Nafisa Ahmad Consultancy | E26: All round | F26: 0 | G26: 200000 | H26: =H25+F26-G26 -> -25340000
B27: 44896 | C27: Legal Cinsultation fees | D27: 2500 | E27: Peramare Kenya | F27: 0 | G27: 1875000 | H27: =H26+F27-G27 -> -27215000
B28: 44901 | C28: A parcel for the MD | G28: 25000 | H28: =H27+F28-G28 -> -27240000
B29: 44908 | C29: Consultancy fee for EV | E29: Transport | G29: 2205000 | H29: =H28+F29-G29 -> -29445000
B30: 44909 | C30: Peramare Energy | E30: Energy | G30: 3352500 | H30: =H29+F30-G30 -> -32797500
B31: 44909 | C31: Nura and Abdul December Salary | G31: 600000 | H31: =H30+F31-G31 -> -33397500
B32: 44909 | C32: Emmanuella and Abdul December Salary | G32: 450000 | H32: =H31+F32-G32 -> -33847500
G33: 0 | H33: =H32+F33-G33 -> -33847500
B34: 44914 | C34: Travel expenses for MD | G34: 1000000 | H34: =H33+F34-G34 -> -34847500
G35: 0 | H35: =H34+F35-G35 -> -34847500
F36: =SUM(F12:F35) -> 0 | G36: =SUM(G12:G35) -> 34847500

Sheet Cash-In-Hand Schedule_
F9: =SUM(H20,H21,H22,H23,H24,H25,H26) -> 33800
B11: Cash-In-Hand/ Imprest Analysis Schedule
J12: Inflow Breakdown | P12: Outflow Breakdown
B13: Date | C13: Description | D13: Transaction Categorisation | E13: Voucher Number | F13: User Unit/ Department | G13: Total Inflow | H13: Total Outflow (Expenses ) | I13: Balance | P13: Assets | S13: Overheads & Salary | AL13: Others
J14: Directors/ Shareholders Contribution | K14: Revenue | L14: Reversal | M14: Interest | N14: Advance Refund | O14: Intra Bank Transfer | P14: Office Equipment | Q14: Furnitures & Fittings | R14: Motor Vehicle | S14: Repairs & Maintenance | T14: Transportation | U14: Staff Welfare, Medicals and Entertainment | V14: Security services | W14: Volunteer Stipend | X14: Staff salary & Allowance | Y14: Professional Fees | Z14: Internet & Telecommunication | AA14: Stationery & office supplies | AB14: Registration, Fees and Dues | AC14: Petty cash | AD14: Printing | AE14: Hotel Accommodation | AF14: Fuel & Lubricant | AG14: Tax | AH14: Training and Development | AI14: Utility | AJ14: Product Logistics (Air, Sea, Rail and Land) | AK14: Bank Charges | AL14: Intra bank transfer | AM14: Reversal
G15: N | H15: N | I15: N | J15: N | K15: N | L15: N | M15: N | N15: N | O15: N | P15: N | Q15: N | R15: N | S15: N | T15: N | U15: N | V15: N | W15: N | X15: N | Y15: N | Z15: N | AA15: N | AB15: N | AC15: N | AD15: N | AE15: N | AF15: N | AG15: N | AH15: N | AI15: N | AK15: N | AL15: N | AM15: N
B16: 44807 | C16: Purchase of bottled water | D16: Staff welfare | E16: PCV/0001 | F16: Admin | H16: 5100 | I16: =G16-H16 -> -5100 | U16: 5100
B17: 44818 | C17: Purchase of bottled water | D17: Staff welfare | E17: PCV/0002 | F17: Admin | H17: 5100 | I17: =I16+G17-H17 -> -10200 | U17: 5100
B18: 44824 | C18: Purchase of bottled water | D18: Staff welfare | E18: PCV/0003 | F18: Admin | H18: 10200 | I18: =I17+G18-H18 -> -20400 | U18: 10200
B19: 44824 | C19: Purchase of dispenser water | D19: Staff welfare | E19: PCV/0004 | F19: Admin | H19: 2500 | I19: =I18+G19-H19 -> -22900 | U19: 2500
B20: 44839 | C20: Reimbursement of staff trasnportation expenses | D20: Transportation | E20: PCV/0005 | F20: HR | H20: 6400 | I20: =I19+G20-H20 -> -29300
B21: 44839 | C21: Tranportation cost for staff | D21: Transportation | E21: PCV/0006 | F21: HR | H21: 5000 | I21: =I20+G21-H21 -> -34300
B22: 44841 | C22: Reimbursement of staff trasnportation expenses | D22: Transportation | E22: PCV/0007 | F22: HR | H22: 3000 | I22: =I21+G22-H22 -> -37300
B23: 44845 | C23: Purchase of bottled water | D23: Staff welfare | E23: PCV/0008 | F23: Admin | H23: 12500 | I23: =I22+G23-H23 -> -49800
B24: 44853 | C24: Cash advance ofr staff transportation | D24: Transportation | E24: PCV/0009 | F24: HR | H24: 2000 | I24: =I23+G24-H24 -> -51800
B25: 44860 | C25: For the purchse of dispenser water | D25: Staff welfare | E25: PCV/0010 | F25: Admin | H25: 2400 | I25: =I24+G25-H25 -> -54200
B26: 44862 | C26: Reimbursement of staff trasnportation expenses | D26: Transportation | E26: PCV/0011 | F26: HR | H26: 2500 | I26: =I25+G26-H26 -> -56700
B27: 44866 | C27: Plumber | D27: Repairs and Maintenance | E27: PCV/0012 | H27: 5000 | I27: =I26+G27-H27 -> -61700
B28: 44874 | C28: Water dispenser | D28: Staff welfare | E28: PCV/0013 | H28: 4000 | I28: =I27+G28-H28 -> -65700
B29: 44881 | C29: Repairs and Maintenance: Motor vehicle clutch | E29: PCV/0014 | H29: 3800 | I29: =I28+G29-H29 -> -69500
B30: 44881 | C30: Staff Welfare: Feeding For Staff | E30: PCV/0015 | H30: 5000 | I30: =I29+G30-H30 -> -74500
B31: 44881 | C31: Purchase of kettles | E31: PCV/0016 | H31: 5000 | I31: =I30+G31-H31 -> -79500
B32: 44882 | C32: Fuel and Lubricants:Fuel for Motor Vehicle | E32: PCV/0017 | H32: 10000 | I32: =I31+G32-H32 -> -89500
B33: 44888 | C33: Staff Welfare: Refreshment for SOGON | E33: PCV/0018 | H33: 15000 | I33: =I32+G33-H33 -> -104500
B34: 44900 | C34: Payment for fuel | D34: Fuel and Lubricants | E34: PCV/0019 | H34: 8000 | I34: =I33+G34-H34 -> -112500
B35: 44903 | C35: Purchase of bottled water | D35: Staff welfare | E35: PCV/0020 | H35: 12500 | I35: =I34+G35-H35 -> -125000
B36: 44911 | C36: Purchase of paper | E36: PCV/0021 | H36: 4000 | I36: =I35+G36-H36 -> -129000
E37: PCV/0022 | I37: =I36+G37-H37 -> -129000
E38: PCV/0023 | I38: =I37+G38-H38 -> -129000
E39: PCV/0024 | I39: =I38+G39-H39 -> -129000
E40: PCV/0025 | I40: =I39+G40-H40 -> -129000
E41: PCV/0026 | I41: =I40+G41-H41 -> -129000
E42: PCV/0027 | I42: =I41+G42-H42 -> -129000
E43: PCV/0028 | I43: =I42+G43-H43 -> -129000
I44: =I43+G44-H44 -> -129000
I45: =I44+G45-H45 -> -129000
I46: =I45+G46-H46 -> -129000
I47: =I46+G47-H47 -> -129000
I48: =I47+G48-H48 -> -129000
I49: =I48+G49-H49 -> -129000
...

Sheet HMO
B10: Bank Analysis Schedule
B12: Date | C12: Description | D12: Transaction Categorisation | E12: User Unit/ Department | F12: Total Inflow | G12: Total Outflow (Expenses ) | H12: Balance
B14: 44887 | C14: HMO Fliers and Checklist | E14: HMO | F14: 0 | G14: 90000 | H14: 90000
B15: 44887 | C15: Basiru Salisu Consultancy | E15: HMO | F15: 0 | G15: 100000 | H15: =H14+F15-G15 -> -10000
B16: 44889 | C16: Consultancy | E16: HMO | F16: 0 | G16: 300000 | H16: =H15+F16-G16 -> -310000
B17: 44889 | C17: Crelio health subscription plan | E17: HMO | F17: 0 | G17: 1045000 | H17: =H16+F17-G17 -> -1355000
B18: 44889 | C18: Health care support systems | E18: HMO | F18: 0 | G18: 2000000 | H18: =H17+F18-G18 -> -3355000
B19: 44889 | C19: Acturial services | E19: HMO | F19: 0 | G19: 2553125 | H19: =H18+F19-G19 -> -5908125
B20: 44889 | C20: HMO Stipends | E20: HMO | F20: 0 | G20: 1300000 | H20: =H19+F20-G20 -> -7208125
B21: 44889 | C21: HMO office documents | E21: HMO | F21: 0 | G21: 170000 | H21: =H20+F21-G21 -> -7378125
B22: 44893 | C22: HMO feeding Allowance | E22: HMO | F22: 0 | G22: 125000 | H22: =H21+F22-G22 -> -7503125
B23: 44895 | C23: IT Subscription | E23: HMO | F23: 0 | G23: 130000 | H23: =H22+F23-G23 -> -7633125
B24: 44904 | C24: HMO Tea Room | E24: HMO | G24: 42000 | H24: =H23+F24-G24 -> -7675125
B25: 44904 | C25: TV for HMO | E25: HMO | G25: 370000 | H25: =H24+F25-G25 -> -8045125
B26: 44904 | C26: Logistics for IT Sky Solutions Meeting | E26: HMO | G26: 26500 | H26: =H25+F26-G26 -> -8071625
B27: 44904 | C27: Development of Health Care Provider (HCP) Network | E27: HMO | G27: 4914525 | H27: =H26+F27-G27 -> -12986150
B28: 44909 | C28: Brochures | E28: HMO | G28: 630000 | H28: =H27+F28-G28 -> -13616150
F29: =SUM(F12:F28) -> 0 | G29: =SUM(G12:G28) -> 13796150

Sheet Agro-Allied
B10: Bank Analysis Schedule
B12: Date | C12: Description | D12: Transaction Categorisation | E12: User Unit/ Department | F12: Total Inflow | G12: Total Outflow (Expenses ) | H12: Balance
F14: N | G14: N | H14: N
F15: 0 | G15: 0 | H15: =F15-G15 -> 0
C16: Hadiza September Salary | E16: Agro-Allied | F16: 0 | G16: 250000 | H16: =H15+F16-G16 -> -250000
C17: Aisha September Salary | E17: Agro-Allied | F17: 0 | G17: 250000 | H17: =H16+F17-G17 -> -500000
B18: 44841 | C18: Nawa property | E18: Agro-Allied | F18: 0 | G18: 10416300 | H18: =H17+F18-G18 -> -10916300
B19: 44858 | C19: Aisha October Salary | E19: Agro-Allied | F19: 0 | G19: 250000 | H19: =H18+F19-G19 -> -11166300
B20: 44858 | C20: Hadiza October Salary | E20: Agro-Allied | F20: 0 | G20: 250000 | H20: =H19+F20-G20 -> -11416300
B21: 44887 | C21: Tchill (Agro Allied) | E21: Agro-Allied | F21: 0 | G21: 10000000 | H21: =H20+F21-G21 -> -21416300
B22: 44887 | C22: Hadiza November Salary | E22: Agro-Allied | F22: 0 | G22: 250000 | H22: =H21+F22-G22 -> -21666300
B23: 44887 | C23: Aisha November Salary | E23: Agro-Allied | F23: 0 | G23: 250000 | H23: =H22+F23-G23 -> -21916300
B24: 44908 | C24: Tchill (Agro Allied) | E24: Agro Allied | G24: 16115766 | H24: =H23+F24-G24 -> -38032066
B25: 44909 | C25: 32 Certificates | E25: Agro Allied | G25: 25600 | H25: =H24+F25-G25 -> -38057666
B26: 44909 | C26: Hadiza and Aisha December Salary | E26: Agro Allied | G26: 500000 | H26: =H25+F26-G26 -> -38557666
F27: =SUM(F12:F26) -> 0 | G27: =SUM(G12:G26) -> 38557666
